Workbook
Name Slicer_Column1: #N/A
Name Slicer_Community: #N/A
Name Slicer_Community1: #N/A
Name Slicer_Community2: #N/A
Name Slicer_PHC: #N/A
Name Slicer_PHC1: #N/A
Name Slicer_PHC2: #N/A
Name Slicer_Religion: #N/A
Name Slicer_Religion1: #N/A
Name Slicer_Religion2: #N/A

Sheet 2023-24
A1: Infant death register - 2023 -2024
A2: Sl.NO | B2: PHC name | C2: Name of Infant, parents and address | D2: Age of the mother | E2: Thayi Card No | F2: Sex | G2: Community | H2: Religion | I2: Date of Birth | J2: Place of Birth | K2: Date of death | L2: Place of death | M2: Birth weight in gms | N2: Most probbable cause of death. | O2: Age at death | P2: Normal/ LSCS | Q2: LMP | R2: EDD | S2: Para | T2: APL/BPL | U2: Education | V2: TT given | Y2: IFA Given | AB2: HB% | AC2: BP | AD2: Late Registration reason | AE2: HRP with reason | AF2: BMI<18 (Please Write) | AG2: Gestation | AH2: Mathru poorna Yojane benificiaries
V3: 1st Dose | W3: II Dose | X3: Booster | Y3: 1st round(last dose 180) | Z3: II round(last dose 360) | AA3: III round
A4: 45017
A5: 1 | B5: Gangolli | C5: B/o Nismah Aabirah Moulana W/o Abdul Nafi Moulana Gudde House J M Road Gangolli | D5: 27 | E5: 129027481306 | F5: Female | G5: Muslim | H5: Muslim | I5: 17.3.23 | J5: Yenepoya Hospital M'lore | K5: 24.3.23 | L5: Falnir Mangalore | M5: 2100gms | N5: Preterm 33weeks Syndromic Baby Congenital Haemolytic Anaemia Neonatal Hyperbillirubinemia | O5: 8days | P5: LSCS | Q5: 26.7.22 | R5: 3.5.23 | S5: G3P2L2 | T5: APL | U5: Puc&Degree | V5: 6.2.23 | W5: 6.3.23 | X5: - | Y5: - | Z5: 7.3.23 | AB5: 10gms | AC5: 110/70 | AD5: No | AE5: NO | AF5: 32 | AG5: 33weeks4days | AH5: NO
A6: 2 | B6: UPHC Manipal | C6: B/o Grithi Harshitha W/o Manjunath Raghvendra Nilaya Near Kadiyali Temple | D6: 29 | E6: 129025963907 | F6: Female | G6: Devadiga | H6: Hindu | I6: 9.9.22 | J6: Adarsh Hospital Puttur | K6: 29.3.23 | L6: KMC Manipal | M6: 2800gms | N6: Myocarditis with Inotrope Resistant Shock Sepsis with Multiorgan Dysfunction Primary Immunodeficiency with Pyogenic Meningitis | O6: 6 m 28 days | P6: Normal | Q6: 30.11.21 | R6: 6.9.22 | S6: Primi | T6: APL | U6: PUC | V6: 21.2.22 | W6: 22.4.22 | X6: - | Y6: 1.3.22 | Z6: 2.4.22 | AA6: 30.5.22 | AB6: 0.11 | AC6: 120/70. | AD6: No | AE6: NO | AF6: 22 | AH6: NO
A7: 3 | B7: Moodabettu | C7: B/o Hensita Roshni Mendonca Vinesh nithin rodrigues dreams shankarpura kurkalu | D7: 29 | E7: 129027174413 | F7: Male | G7: Chrischian | H7: Christain | I7: 10.03.2023 | J7: C.S.I hospital udupi | K7: 30.3.23 | L7: kmc manipal | M7: 2800gms | N7: Complex congenital heart disease Interrupted aortic arch/Pda/Aorto pulmonary window Severe pulmonary artery HTN/AGA/Infant of diabetic mother. | O7: 20 days | P7: LSCS | Q7: 17.6.22 | R7: 24.3.23 | S7: G2ab1 | T7: APL | U7: Degree | V7: 14.9.22 | W7: 14.10.22 | X7: - | Y7: 13.9.22 | Z7: 10.10.22 | AA7: 9.11.22 | AB7: 0.126 | AC7: 120\80 | AD7: No | AE7: NO | AF7: 26 | AH7: Yes
A8: 45047
A9: 4 | B9: FPAI | C9: B/o Meena devi W/o Nikilesh Kumar, Rent House, Horangrapady Near C J Church Padu bailoor 76 Badagabettu | D9: 30 | E9: 129027428961 | F9: Female | G9: Hindu | I9: 30.4.23 | J9: MCH Udupi | K9: 30.4.23 | L9: Wenlock Hospital M'lore | M9: 800gms | N9: Premature with respiratory distress | O9: 1day | P9: Normal | Q9: 29.10.22 | R9: 5.8.23 | S9: G4P3L3 | T9: No ration card | U9: No education | V9: 2.2.23 | W9: 4.3.23 | X9: - | Y9: 2.2.23 | Z9: 4.3.23 | AA9: 6.4.23 | AB9: 0.12 | AC9: 110/70 | AD9: No | AE9: NO | AF9: 21 | AH9: NO
A10: 5 | B10: Padubidri | C10: B/o Divya G W/o Santhosh Guthigethota Hejamady Padubidri Udupi | D10: 28 | E10: 129027157496 | F10: Male | G10: Hindu | I10: 21.3.23 | J10: KMC Attavara | K10: 10.5.23 | L10: KMC Attavara | M10: 2690gms | N10: Term AGA/Neonatal sepsis meconium aspiration syndrome | O10: 49days | P10: LSCS | Q10: 1.7.22 | R10: 8.4.23 | S10: primi | T10: BPL | U10: BA | V10: 23.9.22 | W10: 10.11.22 | X10: - | Y10: 9.9.22 | Z10: 9.10.22 | AA10: 10.11.22 | AB10: 0.135 | AC10: 120/80 | AD10: No | AE10: NO | AF10: 26 | AH10: yes
A11: 6 | B11: Kollur | C11: B/o Jayanthi Raghavana, Hegdebettu, Kolluru | D11: 32 | E11: 129020834647 | F11: Male | G11: Hindu | I11: 18.4.23 | J11: KMC Manipal | K11: 28.4.23 | L11: KMC Manipal | M11: 850gms | N11: EARLY ONSET NEONETAL SEPSIS/SEPTIC SHOCK MODERATE PAH VERY PRETERM (31+3)/EXTREMELY LOW BIRTH WEIGHT/SGA | O11: 10days | P11: LSCS | Q11: 10.9.22 | R11: 17.6.23 | S11: G3 | T11: BPL | U11: 10th | V11: 9.11.22 | W11: 10.12.22 | X11: - | Y11: 24.3.23 | AB11: 0.12 | AC11: 110/70 | AD11: No | AE11: Preeclampsia | AF11: 25 | AG11: 31weeks | AH11: NO
A12: 7 | B12: Ajekar | C12: B/o Kushala W/o Prakasha Gowda ST colony, Mangala Nivasa Paithala, Andaru | D12: 31 | E12: 129022447845 | F12: Male | G12: ST | H12: Hindu | I12: 18.4.23 | J12: G H Karkala | K12: 18.5.23 | L12: Home | M12: 1815gms | N12: Sudden Infant death syndrome | O12: 1m1day | P12: normal | Q12: 3.8.22 | R12: 10.5.23 | S12: G3P2L2 | T12: BPL | U12: 5th&7th | X12: 1.12.22 | Y12: 9.11.22 | Z12: 9.1.23 | AA12: 9.3.23 | AB12: 0.106 | AC12: 110/80 | AD12: No | AE12: No | AF12: 22 | AG12: 36weeks | AH12: Yes
A13: 45078
A14: 8 | B14: Kemmannu | C14: B/o Joshna Swain W/o Santhosh Kumar Swain Gujjarbettu Kemmannu | D14: 25 | E14: 129027360903 | F14: Male | H14: Hindu | I14: 14.6.23 | J14: MCH Udupi | K14: 14.6.23 | L14: On the way to Hospital (108) | M14: 2600gms | N14: Severe birth asphyxia | O14: 1day | P14: LSCS | Q14: 8.9.22 | R14: 15.6.23 | S14: G1 | T14: BPL | U14: 5th&7th | V14: 9.1.23 | W14: 25.2.23 | X14: - | Y14: 4.1.23 | Z14: 6.2.23 | AA14: 9.3.23 | AB14: 0.105 | AC14: 110/60 | AD14: No | AE14: NO | AF14: 24.9 | AH14: NO
A15: 9 | B15: Kemmannu | C15: Dakshayini K C C/o Suresh 3rd cross Rajivnagara Nejar | D15: 31 | E15: 129027378656 | F15: Female | H15: Hindu | I15: 17.5.23 | J15: KMC Manipal | K15: 4.6.23 | L15: KMC Manipal | M15: 1150gms | N15: Preterm delivery necrotising enterocolitis late onset acinobacter sepsis with meningitis | O15: 19days | P15: LSCS | Q15: 23.10.22 | R15: 30.7.23 | S15: Primi | T15: BPL | U15: D-Ed | V15: 21.2.23 | W15: 21.3.23 | X15: - | Y15: 16.2.23 | Z15: 15.3.23 | AA15: 13.4.23 | AB15: 0.13 | AC15: 180/110 | AD15: No | AE15: NO | AF15: 21 | AH15: NO
A16: 10 | B16: Moodabettu | C16: B/o Mumtaz W/o Shamshuddin Global residency Katpady | D16: 31 | E16: 129027229096 | F16: Female | G16: Muslim | H16: Muslim | I16: 23.5.23 | J16: Moodabidri | K16: 24.5.23 | L16: A J Hospital M'lore | M16: 2900gms | N16: Refractory cardiac arrest/Severe Meconium aspiration syndrome | O16: 1day | P16: LSCS | Q16: 29.8.22 | R16: 5.6.23 | S16: G3 | T16: APL | U16: 12th | V16: 4.11.22 | W16: 14.2.23 | X16: - | Y16: 21.10.22 | Z16: 15.11.22 | AA16: 7.12.22 | AB16: 0.122 | AC16: 120/80 | AD16: No | AE16: NO | AF16: 26 | AG16: 35weeks | AH16: yes
A17: 11 | B17: Shankaranarayana | C17: B/o Supreetha W/o Sandeep Kumar Shetty Hanbinagadde Gudibettu Ampar | D17: 31 | E17: 129027299270 | F17: Male | G17: Shetty | H17: Hindu | I17: 9.3.23 | J17: KMC Manipal | K17: 27.5.23 | L17: KMC Manipal | M17: 885gms | N17: Severe Chronic Lung disease sever pneumonia extreme Prematurity | O17: 2month19days | P17: LSCS | Q17: 6.9.22 | R17: 13.6.23 | S17: Primi | T17: APL | U17: B.P.T | V17: 7.12.22 | W17: 13.1.23 | X17: - | Y17: _ | Z17: 9.2.23 | AB17: 0.084 | AC17: 140/80 | AD17: No | AE17: NO | AF17: 27 | AG17: 26weeks | AH17: NO
A18: 12 | B18: Kollur | C18: B/o Nethravathi W/o Nagaraja Poojary Chodra Angadimane Golihole | D18: 26 | E18: 129027418480 | F18: Male | G18: Poojary | H18: Hindu | I18: 21.5.23 | J18: KMC Manipal | K18: 30.5.23 | L18: KMC Manipal | M18: 750gms | N18: Necrotizing enterocololitis stage II respiratory distress syndrome extreme prematurity | O18: 9days | P18: Normal | Q18: 21.11.22 | R18: 28.8.23 | S18: G2 | T18: BPL | U18: PUC | V18: 8.3.23 | W18: 12.4.23 | X18: - | Y18: 22.4.23 | AB18: 0.132 | AC18: 100/70 | AD18: No | AE18: NO | AF18: 29 | AG18: 25weeks6days | AH18: NO
A19: 13 | B19: Kollur | C19: B/o Nethravathi W/o Nagaraja Poojary Chodra Angadimane Golihole | D19: 26 | E19: 129027418480 | F19: Male | G19: Poojary | H19: Hindu | I19: 21.5.23 | J19: KMC Manipal | K19: 23.5.23 | L19: KMC Manipal | M19: 795gms | N19: Pulmonary Hemorrhage left tension pnemothorax extreme PT/ELBWAGA/Severe RDS/DCDA twin2 | O19: 3days | P19: Normal | Q19: 21.11.22 | R19: 28.8.23 | S19: G3 | T19: BPL | U19: PUC | V19: 8.3.23 | W19: 12.4.23 | X19: - | Y19: 22.4.23 | AB19: 0.13 | AC19: 100/70 | AD19: No | AE19: NO | AF19: 29 | AG19: 25weeks6days | AH19: NO | AI19: Audited DC
A20: 45108
A21: 14 | B21: Kumbhashi | C21: B/o Priya W/o Babu, Kamthyarbettu Beejadi Kumbhashi | D21: 30 | E21: 129027195374 | F21: Female | H21: Hindu | I21: 16.4.23 | J21: G H Kundapura | K21: 12.7.23 | L21: KMC Manipal | M21: 1820gms | N21: Severe pulmonary artery Hypertension Bronchopneumonia failure to thrive, Lactic Acidosis | O21: 2m26days | P21: Normal | Q21: 7.8.22 | R21: 14.5.23 | S21: Primi | T21: BPL | U21: PUC | V21: 20.9.22 | W21: 27.10.22 | X21: - | Y21: - | Z21: 27.3.23 | AB21: 12.8gms | AC21: 100/70 | AD21: No | AE21: NO | AF21: 18 | AG21: 32weeks | AI21: Audited DC
A22: 15 | B22: Vandse | C22: Suveeksha B/o Vinoda W/o Surendra Poojary Kullamballi Keradi | D22: 29 | E22: 129027286635 | F22: Female | G22: Poojary | H22: Hindu | I22: 6.4.23 | J22: Adarsh Hospital Kundapura | K22: 17.7.23 | L22: Home(Kullamballi) | M22: 2700gms | N22: Wolmans Disease secondary Hemophagocytic Lymphohistiocytosis acute on chronic liver disease | O22: 3m11days | P22: Normal | Q22: 7.7.22 | R22: 14.4.23 | S22: Primi | T22: BPL | U22: BA/Bcom | V22: 3.10.22 | W22: 11.11.22 | X22: - | Y22: 23.3.23 | AB22: 11gms | AC22: 110/70 | AD22: No | AE22: NO | AF22: 17.8 | AG22: 39weeks
A23: 16 | B23: Maravanthe | C23: B/o Sabiyabanu W/o Usman Bairy W/o Abdul, Ganesha Nagara Navunda | D23: 27 | E23: 129019529049 | F23: Male | G23: Muslim | H23: Muslim | I23: 5.7.23 | J23: G H Goa | K23: 7.7.23 | L23: Medical College Goa | M23: 1100gms | N23: Pneumothorax extreme prematurity extreme low birth weight | O23: 3days | P23: Normal | Q23: 26.12.22 | R23: 3.10.23 | S23: G3P2L2 | T23: BPL | U23: 8th | V23: 9.2.23 | W23: 12.3.23 | X23: - | Y23: 1.7.23 | AB23: 12.7gms | AC23: 110/80 | AD23: No | AE23: NO | AG23: 27weeks
A24: 17 | B24: Hebri | C24: B/o Radhika W/o Dinesh Naik Hebri | D24: 25 | E24: 129027319840 | F24: Female | G24: Kudubi | H24: Hindu | I24: 19.7.23 | J24: KMC Manipal | K24: 20.7.23 | L24: KMC Manipal | M24: 2300gms | N24: Hypoxic Ischemic Encephalopathy stage 3rd Dysmorphic facies/perinal asphyxia/shock/severe anaemia/coagulopathy, Late preterm(35+4weeks) AGA/LBW | O24: 4hours36minutes | P24: LSCS | Q24: 12.11.22 | R24: 19.8.23 | S24: Primi | T24: BPL | U24: Puc&PUC | V24: 22.12.22 | W24: 9.2.23 | X24: - | Y24: 9.2.23 | Z24: 9.3.23 | AA24: 9.4.23 | AB24: 9.4gms | AC24: 110/70 | AD24: No | AE24: NO | AF24: 18 | AG24: 35+4weeks | AH24: yes
A25: 18 | B25: Kaup | C25: B/o Ozala Anjum 1-152/2 Iqbal Manzil , Kote, Near Koppalangadi Mallar | D25: 37 | E25: 129020188805 | F25: Male | G25: Muslim | H25: Muslim | I25: 2.7.23 | J25: Lady Goschen Hosptial M'lore | K25: 6.7.23 | L25: Lady Goschen Hosptial M'lore | M25: 640gms | N25: Extreme prematurity extreme low birth weight | O25: 4days | P25: LSCS | Q25: 24.12.22 | R25: 1.10.23 | S25: G3P2L3 | T25: APL | U25: Degree | V25: 23.3.23 | W25: 23.4.23 | X25: - | Y25: 23.3.23 | Z25: 23.4.23 | AA25: 23.5.23 | AB25: 11.5gms | AC25: 130/70 | AD25: No | AE25: NO | AG25: 26weeks | AH25: yes
A26: 19 | B26: Malpe | C26: Thanusha B/o Savithri Harish Kola Malpe | D26: 40 | E26: 129027314532 | F26: Female | G26: Mogaveer | H26: Hindu | I26: 11.3.23 | J26: KMC Manipal | K26: 8.7.23 | L26: KMC Manipal | M26: 1020gms | N26: Intra Cerebral Haemorrhage, severe Encephalopathy Severe anaemia coagulopathy | O26: 3 1/2 months | P26: LSCS | Q26: 7.8.22 | R26: 14.5.23 | S26: Primi | T26: APL | U26: degree | V26: 11.11.22 | W26: 13.12.22 | X26: - | Y26: 24.11.23 | Z26: 23.12.23 | AA26: 23.1.23 | AB26: 12gms | AC26: 110/70 | AD26: No | AE26: NO | AF26: 20 | AG26: 29weeks | AH26: yes
A27: 20 | B27: Avarse | C27: Samraksha B/o Bharathi W/o Santhosh Kelachakkerbettu Vandaru Avarse | D27: 36 | E27: 129016451039 | F27: Female | H27: Hindu | I27: 23.5.23 | J27: G H Kundapura | K27: 17.7.23 | L27: Home | M27: 3420gms | N27: Milk Aspiration | O27: 56days | P27: Normal | Q27: 27.8.22 | R27: 3.6.23 | S27: G2P1L1 | T27: BPL | U27: 10th&10th | V27: 31.10.22 | W27: 18.12.22 | X27: - | Y27: 30.11.22 | Z27: 30.12.22 | AA27: 28.1.23 | AB27: 10.8gms | AC27: 110/70 | AD27: No | AE27: NO | AF27: 18 | AG27: 33weeks | AH27: yes
A28: 45139
A29: 21 | B29: Basrur | C29: B/o Shridevi W/o Prasad Kumar Kandavara Basrur | D29: 24 | E29: 129024250991 | F29: Female | G29: Shetty | H29: Hindu | I29: 6.6.23 | J29: A J hospiral M'lore | K29: 23.8.23 | L29: Home(Basrur) | M29: 2900gms | N29: Cardiorespiratory failure with septicemia with sacro Coccygeak Teratoma operated transient abnormal Amyelopoisis AML/Megakaryocytic Downs Syndrome moderate ASD with small PDA | O29: 2m17days | P29: LSCS | Q29: 19.9.22 | R29: 26.6.23 | S29: G2P1L1 | T29: BPL | U29: B.A | X29: 27.2.23 | Y29: 27.5.23 | AB29: 11gms | AC29: 110/60 | AD29: No | AE29: Previous LSCS | AF29: 18 | AG29: 32weeks | AH29: NO
A30: 22 | B30: Kirimanjeshwara | C30: B/o Mallika, S/o Sathish Shetty Aparna Nilaya Kalthodu | D30: 34 | E30: 129027265170 | F30: Male | G30: Shetty | H30: Hindu | I30: 3.4.23 | J30: KMC Manipal | K30: 6.8.23 | L30: KMC Manipal | M30: 905gms | N30: Chronic Lung Disease, Chronic Pulmonary Artery Hypertension, Respiratory Distress Syndrome | O30: 4 Month(125days) | P30: LSCS | Q30: 7.9.22 | R30: 14.5.23 | S30: II | T30: BPL | U30: B.A | V30: 20.12.22 | W30: 21.2.23 | Y30: 7.3.23 | AB30: 13gms | AC30: 144/90 | AE30: Previous LSCS | AF30: 27 | AG30: 29weeks4days | AH30: NO
A31: 23 | B31: Maravanthe | C31: B/o Nethra W/o Husein Uroof, Prasanna Vesadari, Tent House Mullikatte Hosadu | D31: 25 | E31: 129016388225 | F31: Female | G31: Hindu | H31: Hindu | I31: 14.8.23 | J31: Lady Goschen Hosptial M'lore | K31: 18.8.23 | L31: Lady Goschen Hosptial M'lore | M31: 800gms | N31: Triplets Prematurity Low birth weight | O31: 5days | P31: LSCS | Q31: 14.1.23 | R31: 21.10.23 | S31: G3P1L1A1 | T31: BPL | U31: 4th | V31: 16.3.23 | W31: 20.4.23 | Z31: 31.7.23 | AB31: 11gms | AC31: 110/70 | AD31: No | AE31: Previous LSCS & Triplets | AF31: 20 | AG31: 28weeks | AH31: NO
A32: 24 | B32: Maravanthe | C32: B/o Nethra W/o Husein Uroof, Prasanna Vesadari, Tent House Mullikatte Hosadu | D32: 25 | E32: 129016388225 | F32: Female | G32: Hindu | H32: Hindu | I32: 14.8.23 | J32: Lady Goschen Hosptial M'lore | K32: 18.8.23 | L32: Lady Goschen Hosptial M'lore | M32: 800gms | N32: Triplets Prematurity Low birth weight | O32: 5days | P32: LSCS | Q32: 14.1.23 | R32: 21.10.23 | S32: G3P1L1A1 | T32: BPL | U32: 4th | V32: 16.3.23 | W32: 20.4.23 | Z32: 31.7.23 | AB32: 11gms | AC32: 110/70 | AD32: No | AE32: Previous LSCS & Triplets | AF32: 20 | AG32: 28weeks | AH32: NO
A33: 25 | B33: Maravanthe | C33: B/o Nethra W/o Husein Uroof, Prasanna Vesadari, Tent House Mullikatte Hosadu | D33: 25 | E33: 129016388225 | F33: Female | G33: Hindu | H33: Hindu | I33: 14.8.23 | J33: Lady Goschen Hosptial M'lore | K33: 18.8.23 | L33: Lady Goschen Hosptial M'lore | M33: 800gms | N33: Triplets Prematurity Low birth weight | O33: 5days | P33: LSCS | Q33: 14.1.23 | R33: 21.10.23 | S33: G3P1L1A1 | T33: BPL | U33: 4th | V33: 16.3.23 | W33: 20.4.23 | Z33: 31.7.23 | AB33: 11gms | AC33: 110/70 | AD33: No | AE33: Previous LSCS & Triplets | AF33: 20 | AG33: 28weeks | AH33: NO
A34: 26 | B34: Palli | C34: B/o Jyothi W/o Ramesh Adapadi Durgadevi Sannidi House Palli | D34: 38 | E34: 129018103624 | F34: Female | H34: Hindu | I34: 24.7.23 | J34: Lady Goschen Hosptial M'lore | K34: 4.8.23 | L34: Lady Goschen Hosptial M'lore | M34: 3300gms | N34: Pulmonary Haemorrhage early onset sepsis(SGA) | O34: 11days15hours | P34: LSCS | Q34: 28.10.22 | R34: 4.8.23 | S34: Primi | T34: BPL | U34: 10th&4th | V34: 11.1.23 | W34: 16.2.23 | Y34: 30.1.23 | Z34: 2.3.23 | AA34: 5.4.23 | AB34: 11.9gms | AC34: 110/60 | AD34: No | AE34: Elderly Primi | AF34: 21.6 | AG34: 38weeks | AH34: Yes
A35: 27 | B35: Palli | C35: B/o Nalini W/o Shekara, Thandava Kunja, Ninjoor Palli | D35: 35 | E35: 129027169513 | F35: Female | G35: ST(Koraga) | H35: Hindu | I35: 26.4.23 | J35: G H Thirthalli | K35: 8.8.23 | L35: Home | M35: 2500gms | N35: Sudden death with excessive cry | O35: 3m13days | P35: FTND | Q35: 7.8.22 | R35: 15.4.23 | S35: Primi | T35: BPL | U35: 6th&9th | V35: 10.10.22 | W35: 10.11.22 | Y35: 10.11.22 | Z35: 10.12.22 | AA35: 10.1.23 | AB35: 11.7gms | AC35: 120/80 | AD35: No | AE35: Elderly Primi | AF35: 21 | AG35: 34weeks | AH35: Yes
A36: 28 | B36: UPHC Manipal | C36: B/o Asha Naik W/o Naveen Naik Ananthanagara Manipal | D36: 32 | E36: 129027535378 | F36: Male | G36: ST(Naik) | H36: Hindu | I36: 27.7.23 | J36: Sri devi Multi Speciality Hospital Honnavara | K36: 28.7.23 | L36: KMC Manipal | M36: 845gms | N36: Extreme Preterm 24weeks 5days LBW Perinal Asphyxia Severe Respiratory distress syndrome Right sided Phnuemothorax Garde 2 IUH pulmonary Haemorrhage | O36: 1day | P36: Normal | Q36: 4.2.23 | R36: 11.11.23 | S36: Primi | T36: BPL | U36: Degree | V36: 15.5.23 | W36: 27.6.23 | Y36: 15.5.23 | Z36: 27.6.23 | AA36: 19.7.23 | AB36: 12gms | AC36: 120/80 | AD36: No | AE36: NO | AG36: 24weeks | AH36: Yes
A37: 29 | B37: Kokkarne | C37: Rishika B/o Vani W/o Late Chandra Naik Thadagal Nenchar Village Kokkarne | D37: 27 | E37: 129018452179 | F37: Female | G37: ST(Naik) | H37: Hindu | I37: 15.5.23 | J37: CHC Brahmavara | K37: 13.8.23 | L37: Home | M37: 2550gms | N37: PM report awaited (KMC Manipal) | O37: 2m27days | P37: Normal | Q37: 28.8.22 | R37: 4.6.23 | S37: G2P3L2 | T37: BPL | U37: 7th | V37: 4.10.22 | W37: 3.11.22 | Y37: 30.11.22 | Z37: 29.12.22 | AA37: 28.1.23 | AB37: 12.6gms | AC37: 110/70 | AD37: No | AE37: NO | AF37: 21 | AG37: 34weeks | AH37: Yes
A38: 30 | B38: Padubidri | C38: B/o Jyothi W/o Deekshith Near Mata, Kanchinadka Padubidri | D38: 34 | E38: 129014460248 | F38: Female | G38: SC | H38: Hindu | I38: 14.8.23 | J38: KMC Manipal | K38: 19.8.23 | L38: KMC Manipal | M38: 685gms | N38: Extreme Preterm Appropriate for gestational age/ELBW Severe respiratory distress syndrome/pulmonary hemorrhage/acute kidney injury | O38: 6days | P38: Normal | Q38: 22.2.23 | R38: 29.11.23 | S38: Primi | T38: BPL | U38: Degree | V38: 11.5.23 | W38: 15.6.23 | X38: - | Y38: 25.5.23 | Z38: 22.6.23 | AA38: 27.7.23 | AB38: 9.6gms | AC38: 110/70 | AD38: No | AE38: Anaemic | AF38: 20 | AG38: 24weeks4days | AH38: Yes
A39: 45170
A40: 31 | B40: Bailoor | C40: B/o Vinoda Kadirapalke Yerlapadi Bailoor | D40: 22 | E40: 129021505073 | F40: Male | G40: SC | H40: Hindu | I40: 17.7.23 | J40: Lady Goschen Hospital M'lore | K40: 13.9.23 | L40: Home | M40: 1465gms | N40: Aspiration? | O40: 59days | P40: LSCS | Q40: 3.11.22 | R40: 10.8.23 | S40: G2P1L1 | T40: BPL | U40: 10th&10th | V40: 29.12.22 | W40: 23.2.23 | Y40: 16.2.23 | Z40: 27.4.23 | AA40: 8.6.23 | AB40: 0.112 | AC40: 119/67 | AD40: No | AE40: Previous LSCS | AF40: 17.84 | AG40: 35weeks+5days | AH40: yes
...

Sheet 2024-25
A2: Sl.NO | B2: PHC name | C2: Name of Infant, parents and address | D2: Age of the mother | E2: Thayi Card No | F2: Sex | G2: Community | H2: Religion | I2: Date of Birth | J2: Place of Birth | K2: Date of death | L2: Place of death | M2: Birth weight in gms | O2: Most probbable cause of death. | P2: Age at death | Q2: Normal/ LSCS | R2: LMP | S2: EDD | T2: Para | U2: APL/BPL | V2: Education | W2: TT given | Z2: IFA Given | AC2: HB% | AD2: BP | AE2: Late Registration reason | AF2: HRP with reason | AG2: BMI<18 (Please Write) | AH2: Gestation | AI2: Mathru poorna Yojane benificiaries
W3: 1st Dose | X3: II Dose | Y3: Booster | Z3: 1st round(last dose 180) | AA3: II round(last dose 360) | AB3: III round
A4: 1 | B4: Byndoor | C4: B/o Poornima W/o Ramachandra Janatha Colony Uppunda | D4: 32 | E4: 129021987641 | F4: Female | G4: Kharvi | H4: Hindu | I4: 4.4.24 | J4: KMC Manipal | K4: 17.4.24 | L4: KMC Manipal | M4: 925gms | N4: LBW , Morderate Prematurity | O4: Early Preterm(31weeks+5day) Extremly low birth weight , Small for gestational age/Birth Asphyxia/Severe respiratory Distress Syndrome Early rescue Surfactant /severe pulmonary Arterial Hypertension Acute Kidney Injury /Hyponatremia/Hypoglycemia/Candida sepsis/Coagulopathy/Pulmonary Haemorrhage | P4: 13days | Q4: LSCS | R4: 26.8.23 | S4: 2.6.24 | T4: G4P1L1A2 | U4: BPL | V4: 10th | W4: 9.11.23 | X4: 1.1.24 | Y4: - | Z4: 1.4.24 | AC4: 10.9gms | AD4: 110/70 | AE4: No | AF4: Previous LSCS | AG4: 22 | AH4: 31weeks5days | AI4: NO
B5: Kemmannu PHC | C5: Balkis banu | D5: 43 | E5: 12902822253 | F5: Male | G5: Muslim | H5: Muslim | I5: 45330 | J5: KMC Manipal | K5: 45393 | L5: KMC Manipal | M5: 2075 gms | N5: Multi Para
A6: 3 | B6: Idu | C6: B/o M Anusha Kumari W/o Shanthiraj Jain Kelagina Karimbyalu Idu | D6: 26 | E6: 129026955634 | F6: Male | G6: Jain | H6: Jain | I6: 12.4.24 | J6: Lady Goschen Hospital M'lore | K6: 16.4.24 | L6: Lady Goschen Hospital M'lore | M6: 2950gms | N6: Others | O6: Multiple Fetal Anomalies Absent Cavum Pellucudum With Septo-Optic Dysplasia? Severe Persistent Pulmonary Hypertension | P6: 3day15hours12m | Q6: LSCS | R6: 8.8.23 | S6: 15.5.24 | T6: G2P1L1 | U6: BPL | V6: M.com PUC | W6: - | X6: - | Y6: 27.12.23 | AB6: 12.3.24 | AC6: 12.6gms | AD6: 120/70 | AE6: No | AF6: Previous LSCS | AG6: 24 | AH6: 34weeks | AI6: Yes
A7: 4 | B7: Korgi | C7: Divani Kumari B/o Pinkidevi Kumari W/o Hareram Paswan , Girija Cashew Factory Asodu Korgi | D7: 34 | E7: 129027788501 | F7: Female | G7: others | H7: Hindu | I7: 9.3.24 | J7: G H Kundapura | K7: 17.5.24 | L7: Home | M7: 2006gms | N7: sids | O7: SIDs | P7: 2m8days | Q7: Normal | R7: 25.6.23 | S7: 1.4.24 | T7: G5P2L2 | V7: Uneducated | W7: 11.8.23 | X7: 12.9.23 | Y7: - | Z7: 11.8.23 | AA7: 11.8.23 | AC7: 10.6gms | AD7: 110/70 | AE7: No | AF7: Rh nagative | AG7: 20 | AH7: 38weeks | AI7: NO
A8: 5 | B8: Byndoor | C8: B/o Bhavya W/o Vinoda Uppinakote Uppunda | D8: 32 | E8: 129027960593 | F8: Male | G8: Kharvi | H8: Hindu | I8: 10.5.24 | J8: Lady Goschen Hospital M'lore | K8: 17.5.24 | L8: Lady Goschen Hospital M'lore | M8: 980gms | N8: LBW, EXTREME PREMATURITY, SEPSIS | O8: Sepsis Prematurity With VLBW | P8: 8days | Q8: LSCS | R8: 22.9.23 | S8: 29.7.24 | T8: G2P1L1 | U8: BPL | V8: BA/Bed | W8: 30.11.23 | X8: 4.1.24 | Y8: - | Z8: 9.4.24 | AC8: 11gms | AD8: 110/70 | AE8: No | AF8: Hypothyrodism | AG8: 15 | AH8: 27weeks | AI8: NO
A9: 6 | B9: Shiroor | C9: B/o Shriraksha W/o Prlash, Subbumane, Tarapathi Paduvary | D9: 29 | E9: 129027194000 | F9: Male | G9: Kharvi | H9: Hindu | I9: 22.4.24 | J9: KMC Manipal | K9: 25.4.24 | L9: Home | M9: 1990gms | N9: MORDERATE PRETERM, | O9: Extreme Preterm Congenital Pneumonia | P9: 3days | Q9: LSCS | R9: 4.10.23 | S9: 11.7.24 | T9: G2P1L0A1 | U9: BPL | V9: Degree/PUC | W9: 6.1.24 | X9: 6.2.24 | Y9: - | Z9: 6.1.24 | AC9: 11.5gms | AD9: 110/80 | AE9: No | AF9: No | AG9: 23 | AH9: 24weeks | AI9: NO
A10: 7 | B10: Brahmavara | C10: B/o Abeeda Mohammed, Brahmavara | D10: 30 | E10: 129025950733 | F10: Male | G10: Muslim | H10: Muslim | I10: 29.2.24 | J10: Gandhi Hospital Udupi | K10: 11.5.24 | L10: Mahesh Hospital Brahmavara | M10: 3200gms | N10: CHD | O10: Fallots Tetrology Cyanotic Spell | P10: 2months | Q10: Normal | R10: 25.5.23 | S10: 4.3.24 | T10: G5 | U10: BPL | V10: Puc&7th | W10: - | X10: - | Y10: 15.9.23 | Z10: 23.8.23 | AA10: 25.9.23 | AB10: 15.10.23 | AC10: 11gms | AD10: 100/60 | AE10: No | AF10: No | AG10: 26 | AH10: 39weeks4days | AI10: NO
A11: 8 | B11: Inna | C11: B/o Swathi W/o Yogish Acharya, Darkas House Kanjarkatte, Inna Santhoor Post | D11: 32 | E11: 129028016904 | F11: Female | G11: Acharya | H11: Hindu | I11: 25.4.24 | J11: A J Hospital Mangalore | K11: 12.5.24 | L11: A J Hospital Mangalore | M11: 1590 | N11: LBW,TWIN,OTHERS | O11: Multi Organ Dysfuction syndrome septic shock bilateral grade 3 intra ventricular hemorrhage with moderate Hydrocephalus neonatal seizures acute kidney injury stage 1 anemia of prematurity moderate respiratory distress syndrome very preterm very low birth weight. | P11: 16days | Q11: LSCS | R11: 28.9.23 | S11: 5.7.24 | T11: G1P0L0 | U11: BPL | V11: Bcom | W11: 26.12.23 | X11: 25.1.24 | Y11: - | Z11: 25.1.24 | AA11: 24.2.24 | AB11: 26.3.24 | AC11: 13.4gms | AD11: 110/70 | AE11: No | AF11: No | AH11: 34weeks4days | AI11: NO
A12: 9 | B12: Inna | C12: B/o Swathi W/o Yogish Acharya, Darkas House Kanjarkatte, Inna Santhoor Post | D12: 32 | E12: 129028016904 | F12: Female | G12: Acharya | H12: Hindu | I12: 25.4.24 | J12: A J Hospital Mangalore | K12: 12.5.24 | L12: A J Hospital Mangalore | M12: 1550 | N12: LBW,TWIN,OTHERS | O12: Multi Organ Dysfuction syndrome septic shock bilateral grade 3 intra ventricular hemorrhage with moderate Hydrocephalus neonatal seizures acute kidney injury stage 1 anemia of prematurity moderate respiratory distress syndrome very preterm very low birth weight. | P12: 16days | Q12: LSCS | R12: 28.9.23 | S12: 5.7.24 | T12: G1P0L1 | U12: BPL | V12: Bcom | W12: 26.12.23 | X12: 25.1.24 | Y12: - | Z12: 25.1.24 | AA12: 24.2.24 | AB12: 26.3.24 | AC12: 13.4gms | AD12: 110/70 | AE12: No | AF12: No | AH12: 34weeks4days | AI12: NO
A13: 10 | B13: Idu PHC | C13: Sanvith B/o Leelavathi W/o Gopala Daivanugraha House, Ballottu, Idu | D13: 34 | E13: 129019608980 | F13: Male | G13: SC | H13: Hindu | I13: 22.3.24 | J13: Lady Goschen Hospital M'lore | K13: 7.5.24 | L13: KMC Manipal | M13: 2580 | N13: Others | O13: Refractory Decompensated Shock Biventricular Failure severe PAH | P13: 1month 15days | Q13: LSCS | R13: 29.9.23 | S13: 6.7.24 | T13: G3P2L2 | U13: BPL | V13: 10th&6th | W13: 16.2.24 | X13: 17.3.24 | Y13: - | Z13: 29.1.24 | AA13: 16.2.24 | AB13: 17.3.24 | AC13: 11.5gms | AD13: 140/80 | AE13: No | AF13: No | AH13: 25weeks | AI13: NO
B14: Malpe PHC

Sheet Sheet1
A2: Sl. No. | B2: Name of Infant, parents and address | C2: Taluk | D2: PHC | E2: Age | F2: Religion | G2: Community | H2: High Risk (Yes / No) | I2: Type of High Risk | AB2: Delivery Type (LSCS / Norma / Induced) | AC2: Gender | AD2: Age of Child at the time of death | AG2: Place of Birth | AH2: Place of Death | AI2: Cause of Death | BE2: Reason for Others | BF2: Preventable Yes / No
I3: Diabetes mellitus | J3: Elderly Primi | K3: Severe Hypertension | L3: Previous Abortion | M3: Low Lying Placenta | N3: Bad Obstetrics History | O3: Aneamia | P3: Sevre Aneamia (Hb<7) | Q3: Preeclampsia | R3: Previous LSCS | S3: Heigh <145 cms | T3: Infectitons like HIV, Sypholiis | U3: Epilpsy / Asthama / Any other Disease | V3: 4 / More Pregnancies | W3: Transverse lie of featus | X3: Tyroid Disease | Y3: IUGR | Z3: Twins / Triplets etc | AA3: Fetal developmental abnormalaitis | AD3: Months | AE3: Days | AF3: Hours | AI3: Low Birth Weight | AJ3: Extreme preterm <28 weeks) | AK3: Early Premature (28-31 weeks) | AL3: Morderate Premature (<32-33 weeks) | AM3: Late Pre-term (34-36 weeks) | AN3: Pneumonia | AO3: Cardiac | AR3: Sepsis | AS3: Respiratory Distress | AT3: Neonatal Asphyxia | AU3: Meconium Aspiration Syndrome | AV3: Necrotinsing Enterocolitis | AW3: Hepatic Cause | AX3: Pneumothorax | AY3: SIDS | AZ3: IUGR | BA3: Hemophagocytic | BB3: Milk Aspiration | BC3: Cronic Liver Disease | BD3: Others
AO4: Myocarditis | AP4: Cardiac Anomoly | AQ4: CHD | BH4: fsadf
A5: 1 | B5: B/o Nismah Aabirah Moulana W/o Abdul Nafi Moulana Gudde House J M Road Gangolli | C5: Kundapura | D5: Gangolli | E5: 27 | F5: Muslim | G5: Muslim | H5: No | AB5: LSCS | AC5: Female | AE5: 8 | AG5: Pvt. Medical College | AH5: Home | AL5: yes | BD5: yes | BE5: Congenital Haemolytic Aneamia, Neonatal Hyper Bilirubilnemia | BF5: No | BH5: Preterm 33weeks Syndromic Baby Congenital Haemolytic Anaemia Neonatal Hyperbillirubinemia
A6: 2 | B6: B/o Grithi Harshitha W/o Manjunath Raghvendra Nilaya Near Kadiyali Temple | C6: Udupi | D6: UPHC Manipal | E6: 29 | F6: Hindu | G6: Devadiga | H6: No | AB6: Normal | AC6: Female | AD6: 6 | AE6: 28 | AG6: Pvt. Hospital | AH6: Pvt. Medical College | AO6: yes | AR6: yes | BF6: No | BH6: Myocarditis with Inotrope Resistant Shock Sepsis with Multiorgan Dysfunction Primary Immunodeficiency with Pyogenic Meningitis
A7: 3 | B7: B/o Hensita Roshni Mendonca Vinesh nithin rodrigues dreams shankarpura kurkalu | C7: Udupi | D7: Moodabettu | E7: 29 | F7: Christian | G7: Christian | H7: No | AB7: LSCS | AC7: Male | AE7: 20 | AG7: Pvt. Hospital | AH7: Pvt. Medical College | AO7: yes | BF7: No | BH7: Complex congenital heart disease Interrupted aortic arch/Pda/Aorto pulmonary window Severe pulmonary artery HTN/AGA/Infant of diabetic mother.
A8: 4 | B8: B/o Meena devi W/o Nikilesh Kumar, Rent House, Horangrapady Near C J Church Padu bailoor 76 Badagabettu | C8: Udupi | D8: FPAI | E8: 30 | F8: Hindu | G8: Lambani | H8: No | AB8: Normal | AC8: Female | AE8: 1 | AG8: Govt. Hospital | AH8: Govt. Hospital | AJ8: Yes | AS8: Yes | BF8: No | BH8: Premature with respiratory distress
A9: 5 | B9: B/o Divya G W/o Santhosh Guthigethota Hejamady Padubidri Udupi | C9: Udupi | D9: Padubidri | E9: 28 | F9: Hindu | G9: Poojary | H9: No | AB9: LSCS | AC9: Male | AD9: 1 | AE9: 19 | AG9: Pvt. Medical College | AH9: Pvt. Medical College | AR9: Yes | AU9: Yes | BF9: Yes | BH9: Term AGA/Neonatal sepsis meconium aspiration syndrome
A10: 6 | B10: B/o Jayanthi Raghavana, Hegdebettu, Kolluru | C10: Kundapura | D10: Kollur | E10: 32 | F10: Hindu | G10: Poojary | H10: Yes | Q10: Yes | AB10: LSCS | AC10: Male | AE10: 10 | AG10: Pvt. Medical College | AH10: Pvt. Medical College | AI10: Yes | AL10: Yes | AR10: Yes | BF10: Yes | BH10: EARLY ONSET NEONETAL SEPSIS/SEPTIC SHOCK MODERATE PAH VERY PRETERM (31+3)/EXTREMELY LOW BIRTH WEIGHT/SGA
A11: 7 | B11: B/o Kushala W/o Prakasha Gowda ST colony, Mangala Nivasa Paithala, Andaru | C11: Karkala | D11: Ajekar | E11: 31 | F11: Hindu | G11: ST | H11: No | AB11: normal | AC11: Male | AD11: 1 | AE11: 1 | AG11: Govt. Hospital | AH11: Home | AY11: Yes | BF11: Yes | BH11: Sudden Infant death syndrome
A12: 8 | B12: B/o Joshna Swain W/o Santhosh Kumar Swain Gujjarbettu Kemmannu | C12: Udupi | D12: Kemmannu | E12: 25 | F12: Hindu | G12: Polai | H12: No | AB12: LSCS | AC12: Male | AE12: 1 | AG12: Govt. Hospital | AH12: Transit | AT12: Yes | BF12: Yes | BH12: Severe birth asphyxia
A13: 9 | B13: Dakshayini K C C/o Suresh 3rd cross Rajivnagara Nejar | C13: Udupi | D13: Kemmannu | E13: 31 | F13: Hindu | G13: SC | H13: No | AB13: LSCS | AC13: Female | AE13: 19 | AG13: Pvt. Medical College | AH13: Pvt. Medical College | AL13: Yes | AR13: Yes | AV13: Yes | BF13: No | BH13: Preterm delivery necrotising enterocolitis late onset acinobacter sepsis with meningitis
A14: 10 | B14: B/o Mumtaz W/o Shamshuddin Global residency Katpady | C14: Udupi | D14: Moodabettu | E14: 31 | F14: Muslim | G14: Muslim | H14: No | AB14: LSCS | AC14: Female | AE14: 1 | AG14: Pvt. Hospital | AH14: Pvt. Medical College | AU14: Yes | BF14: Yes | BH14: Refractory cardiac arrest/Severe Meconium aspiration syndrome
A15: 11 | B15: B/o Supreetha W/o Sandeep Kumar Shetty Hanbinagadde Gudibettu Ampar | C15: Kundapura | D15: Shankaranarayana | E15: 31 | F15: Hindu | G15: Shetty | H15: No | AB15: LSCS | AC15: Male | AD15: 2 | AE15: 19 | AG15: Pvt. Medical College | AH15: Pvt. Medical College | AJ15: Yes | AN15: Yes | BF15: No | BH15: Severe Chronic Lung disease sever pneumonia extreme Prematurity
A16: 12 | B16: B/o Nethravathi W/o Nagaraja Poojary Chodra Angadimane Golihole | C16: Kundapura | D16: Kollur | E16: 26 | F16: Hindu | G16: Poojary | H16: No | AB16: Normal | AC16: Male | AE16: 9 | AG16: Pvt. Medical College | AH16: Pvt. Medical College | AJ16: Yes | AS16: Yes | AV16: Yes | BF16: No | BH16: Necrotizing enterocololitis stage II respiratory distress syndrome extreme prematurity
A17: 13 | B17: B/o Nethravathi W/o Nagaraja Poojary Chodra Angadimane Golihole | C17: Kundapura | D17: Kollur | E17: 26 | F17: Hindu | G17: Poojary | H17: No | AB17: Normal | AC17: Male | AE17: 3 | AG17: Pvt. Medical College | AH17: Pvt. Medical College | AJ17: Yes | AS17: Yes | BF17: No | BH17: Pulmonary Hemorrhage left tension pnemothorax extreme PT/ELBWAGA/Severe RDS/DCDA twin2
A18: 14 | B18: B/o Priya W/o Babu, Kamthyarbettu Beejadi Kumbhashi | C18: Kundapura | D18: Kumbhashi | E18: 30 | F18: Hindu | G18: SC | H18: No | AB18: Normal | AC18: Female | AD18: 2 | AE18: 26 | AG18: Govt. Hospital | AH18: Pvt. Medical College | AN18: Yes | BF18: No | BH18: Severe pulmonary artery Hypertension Bronchopneumonia failure to thrive, Lactic Acidosis
A19: 15 | B19: Suveeksha B/o Vinoda W/o Surendra Poojary Kullamballi Keradi | C19: Kundapura | D19: Vandse | E19: 29 | F19: Hindu | G19: Poojary | H19: No | AB19: Normal | AC19: Female | AD19: 3 | AE19: 11 | AG19: Pvt. Hospital | AH19: Home | AW19: Yes | BD19: Yes | BE19: Wolmans Disease | BF19: No | BH19: Wolmans Disease secondary Hemophagocytic Lymphohistiocytosis acute on chronic liver disease
A20: 16 | B20: B/o Sabiyabanu W/o Usman Bairy W/o Abdul, Ganesha Nagara Navunda | C20: Kundapura | D20: Maravanthe | E20: 27 | F20: Muslim | G20: Muslim | H20: No | AB20: Normal | AC20: Male | AE20: 3 | AG20: Govt. Hospital | AH20: Pvt. Medical College | AI20: Yes | AJ20: Yes | AX20: Yes | BF20: No | BH20: Pneumothorax extreme prematurity extreme low birth weight
A21: 17 | B21: B/o Radhika W/o Dinesh Naik Hebri | C21: Karkala | D21: Hebri | E21: 25 | F21: Hindu | G21: Kudubi | H21: No | AB21: LSCS | AC21: Female | AF21: 4 | AG21: Pvt. Medical College | AH21: Pvt. Medical College | BD21: Yes | BE21: Hypoxic Ischemic Encephalopathy stage 3rd Dysmorphic facies/perinal asphyxia/shock/severe anaemia/coagulopathy, Late preterm(35+4weeks) AGA/LBW | BF21: No | BH21: Hypoxic Ischemic Encephalopathy stage 3rd Dysmorphic facies/perinal asphyxia/shock/severe anaemia/coagulopathy, Late preterm(35+4weeks) AGA/LBW
A22: 18 | B22: B/o Ozala Anjum 1-152/2 Iqbal Manzil , Kote, Near Koppalangadi Mallar | C22: Udupi | D22: Kaup | E22: 37 | F22: Muslim | G22: Muslim | H22: No | AB22: LSCS | AC22: Male | AE22: 4 | AG22: Govt. Hospital | AH22: Govt. Hospital | AI22: Yes | AJ22: Yes | BF22: No | BH22: Extreme prematurity extreme low birth weight
A23: 19 | B23: Thanusha B/o Savithri Harish Kola Malpe | C23: Udupi | D23: Malpe | E23: 40 | F23: Hindu | G23: Mogaveer | H23: No | AB23: LSCS | AC23: Female | AD23: 3 | AE23: 15 | AG23: Pvt. Medical College | AH23: Pvt. Medical College | BD23: Yes | BE23: Intra Cerebral Haemorrhage, severe Encephalopathy Severe anaemia coagulopathy | BF23: No | BH23: Intra Cerebral Haemorrhage, severe Encephalopathy Severe anaemia coagulopathy
A24: 20 | B24: Samraksha B/o Bharathi W/o Santhosh Kelachakkerbettu Vandaru Avarse | C24: Udupi | D24: Avarse | E24: 36 | F24: Hindu | G24: Kulal | H24: No | AB24: Normal | AC24: Female | AD24: 1 | AE24: 26 | AG24: Govt. Hospital | AH24: Home | BB24: Yes | BF24: Yes | BH24: Milk Aspiration
A25: 21 | B25: B/o Shridevi W/o Prasad Kumar Kandavara Basrur | C25: Kundapura | D25: Basrur | E25: 24 | F25: Hindu | G25: Shetty | H25: Yes | R25: Yes | AB25: LSCS | AC25: Female | AD25: 2 | AE25: 17 | AG25: Pvt. Medical College | AH25: Home | BD25: Yes | BE25: AML/Megakaryocytic Downs Syndrome moderate ASD with small PDA | BF25: No | BH25: Cardiorespiratory failure with septicemia with sacro Coccygeak Teratoma operated transient abnormal Amyelopoisis AML/Megakaryocytic Downs Syndrome moderate ASD with small PDA
A26: 22 | B26: B/o Mallika, S/o Sathish Shetty Aparna Nilaya Kalthodu | C26: Kundapura | D26: Kirimanjeshwara | E26: 34 | F26: Hindu | G26: Shetty | H26: Yes | R26: Yes | AB26: LSCS | AC26: Male | AD26: 4 | AE26: 5 | AG26: Pvt. Medical College | AH26: Pvt. Medical College | AI26: Yes | AS26: Yes | BD26: Yes | BE26: Chronic Lung Disease, Chronic Pulmonary Artery Hypertension, | BF26: No | BH26: Chronic Lung Disease, Chronic Pulmonary Artery Hypertension, Respiratory Distress Syndrome
A27: 23 | B27: B/o Nethra W/o Husein Uroof, Prasanna Vesadari, Tent House Mullikatte Hosadu | C27: Kundapura | D27: Maravanthe | E27: 25 | F27: Hindu | G27: Hindu | H27: Yes | R27: Yes | Z27: Yes | AB27: LSCS | AC27: Female | AE27: 5 | AG27: Govt. Hospital | AH27: Govt. Hospital | AI27: Yes | AJ27: Yes | BF27: No | BH27: Triplets Prematurity Low birth weight
A28: 24 | B28: B/o Nethra W/o Husein Uroof, Prasanna Vesadari, Tent House Mullikatte Hosadu | C28: Kundapura | D28: Maravanthe | E28: 25 | F28: Hindu | G28: Hindu | H28: Yes | R28: Yes | Z28: Yes | AB28: LSCS | AC28: Female | AE28: 5 | AG28: Govt. Hospital | AH28: Govt. Hospital | AI28: Yes | AJ28: Yes | BF28: No | BH28: Triplets Prematurity Low birth weight
A29: 25 | B29: B/o Nethra W/o Husein Uroof, Prasanna Vesadari, Tent House Mullikatte Hosadu | C29: Kundapura | D29: Maravanthe | E29: 25 | F29: Hindu | G29: Hindu | H29: Yes | R29: Yes | Z29: Yes | AB29: LSCS | AC29: Female | AE29: 5 | AG29: Govt. Hospital | AH29: Govt. Hospital | AI29: Yes | AJ29: Yes | BF29: No | BH29: Triplets Prematurity Low birth weight
A30: 26 | B30: B/o Jyothi W/o Ramesh Adapadi Durgadevi Sannidi House Palli | C30: Karkala | D30: Palli | E30: 38 | F30: Hindu | G30: Achari | H30: Yes | J30: Yes | AB30: LSCS | AC30: Female | AE30: 11 | AG30: Govt. Hospital | AH30: Govt. Hospital | AR30: Yes | BF30: Yes | BH30: Pulmonary Haemorrhage early onset sepsis(SGA)
A31: 27 | B31: B/o Nalini W/o Shekara, Thandava Kunja, Ninjoor Palli | C31: Karkala | D31: Palli | E31: 35 | F31: Hindu | G31: ST(Koraga) | H31: Yes | J31: Yes | AB31: FTND | AC31: Female | AD31: 3 | AE31: 13 | AG31: Govt. Hospital | AH31: Home | BB31: Yes | BF31: Yes | BH31: Sudden death with excessive cry
A32: 28 | B32: B/o Asha Naik W/o Naveen Naik Ananthanagara Manipal | C32: Udupi | D32: UPHC Manipal | E32: 32 | F32: Hindu | G32: ST(Naik) | H32: No | AB32: Normal | AC32: Male | AE32: 1 | AG32: Pvt. Hospital | AH32: Pvt. Medical College | AI32: Yes | AJ32: Yes | BF32: No | BH32: Extreme Preterm 24weeks 5days LBW Perinal Asphyxia Severe Respiratory distress syndrome Right sided Phnuemothorax Garde 2 IUH pulmonary Haemorrhage
A33: 29 | B33: Rishika B/o Vani W/o Late Chandra Naik Thadagal Nenchar Village Kokkarne | C33: Udupi | D33: Kokkarne | E33: 27 | F33: Hindu | G33: ST(Naik) | H33: No | AB33: Normal | AC33: Female | AD33: 2 | AE33: 27 | AG33: Govt. Hospital | AH33: Home | AR33: Yes | BB33: Yes | BF33: Yes | BH33: PM report awaited (KMC Manipal)
A34: 30 | B34: B/o Jyothi W/o Deekshith Near Mata, Kanchinadka Padubidri | C34: Udupi | D34: Padubidri | E34: 34 | F34: Hindu | G34: SC | H34: Yes | O34: Yes | AB34: Normal | AC34: Female | AE34: 6 | AG34: Pvt. Medical College | AH34: Pvt. Medical College | BB34: Yes | BF34: No | BH34: Extreme Preterm Appropriate for gestational age/ELBW Severe respiratory distress syndrome/pulmonary hemorrhage/acute kidney injury
A35: 31 | B35: B/o Vinoda Kadirapalke Yerlapadi Bailoor | C35: Karkala | D35: Bailoor | E35: 22 | F35: Hindu | G35: SC | H35: Yes | R35: Yes | AB35: LSCS | AC35: Male | AD35: 1 | AE35: 29 | AG35: Govt. Hospital | AH35: Home | BB35: Yes | BF35: Yes | BH35: Aspiration?
A36: 32 | B36: B/o Vanitha Devadiga W/o Dinesh Devadiga Kamil Darkas Jarkala Yerlapady | C36: Karkala | D36: Bailoor | E36: 34 | F36: Hindu | G36: Devadiga | H36: Yes | K36: Yes | R36: Yes | AB36: LSCS | AC36: Male | AE36: 17 | AG36: Pvt. Medical College | AH36: Pvt. Medical College | AR36: Yes | BF36: No | BH36: Septic shock culture positive sepsis Ecoli, Extreme Preterm 27+weeks AGA
A37: 33 | B37: B/o Padmavathi W/o Ravi Guddakibettu Yennehole | C37: Karkala | D37: Ajekar | E37: 31 | F37: Hindu | G37: SC | H37: No | AB37: LSCS | AC37: Male | AD37: 1 | AE37: 3 | AG37: Govt. Hospital | AH37: Home | AI37: Yes | AS37: Yes | BF37: Yes | BH37: Prematurity LBW Respiratory Distress
A38: 34 | B38: B/o Soni W/o Sandeep Peradka Mala | C38: Karkala | D38: Mala | E38: 17 | F38: Hindu | G38: SC | H38: Yes | Z38: Yes | AB38: LSCS | AC38: Male | AE38: 6 | AG38: Govt. Hospital | AH38: Govt. Hospital | AL38: Yes | BD38: Yes | BE38: Pregnancy induced Hypertension | BF38: No | BH38: Awaiting PM report
A39: 35 | B39: Mohammed Nuhu Alisha W/o Mohammed Nadim, Near Julpa store Kandlur | C39: Kundapura | D39: Kandlur | E39: 19 | F39: Muslim | G39: Muslim | H39: No | AB39: Normal | AC39: Male | AD39: 2 | AE39: 19 | AG39: Pvt. Medical College | AH39: Home | BD39: Yes | BE39: Cardio Pulmonary arrest , Carpenter syndrome2, Hypoxic ischemic encephalopathy with sepsis | BF39: No | BH39: Cardio Pulmonary arrest , Carpenter syndrome2, Hypoxic ischemic encephalopathy with sepsis
A40: 36 | B40: B/o Mubeen Kausar W/o Mohammed Sanavulla, Kabrady Kandlur | C40: Kundapura | D40: Kandlur | E40: 41 | F40: Muslim | G40: Muslim | H40: Yes | I40: Yes | L40: Yes | O40: Yes | AB40: Normal | AC40: Male | AE40: 7 | AG40: Pvt. Medical College | AH40: Pvt. Medical College | AJ40: Yes | AS40: Yes | BF40: No | BH40: Severe respiratory distress syndrome Extreme preterm AGA LBW
A41: 37 | B41: B/o Rameeza W/o Navaz Ahamed Main Road Moodugopadi | C41: Kundapura | D41: Kumbhashi | E41: 25 | F41: Muslim | G41: Muslim | H41: Yes | L41: Yes | AB41: Normal | AC41: Male | AD41: 1 | AE41: 6 | AG41: Govt. Hospital | AH41: Home | BD41: Yes | BE41: Transient taechypnea of newborn single umbalical artery and correction of Aorta with PDA moderate pulmonary hypertension | BF41: No | BH41: Transient taechypnea of newborn single umbalical artery and correction of Aorta with PDA moderate pulmonary hypertension
...

Sheet 2024-25 report
A1: Detailed Infant Death Report for the year 2024-25 (April 24 to November 24)
H2: Type of High Risk | AJ2: Cause of Death
A3: Sl. No | B3: Name of Infant, parents and address | L3: Aneamia | AE3: Age of Child at the time of death | AO3: Pneumonia | AR3: Cardiac
C4: Taluk | D4: PHC | E4: Religion | F4: Community | G4: High Risk (Yes / No) | H4: Diabetes mellitus | I4: RH '- ve' | J4: Elderly Primi | K4: Hypertensive Diorders | L4: Mild | M4: Morderate | N4: Sevre Aneamia | O4: BMI < 18 | P4: Previous LSCS | Q4: Heigh <145 cms | R4: Infectitons like HIV, Sypholiis | S4: Epilpsy / Asthama / Any other Disease | T4: 4 / More Pregnancies | U4: Multi Gravida | V4: Previous Abortion | W4: Transverse lie of featus | X4: Tyroid Disease | Y4: Psychiatric Illness | Z4: IUGR | AA4: Twins / Triplets etc | AB4: Fetal developmental abnormalaitis | AC4: Delivery Type (LSCS / Norma / Induced) | AD4: Gender | AE4: Months | AF4: Days | AG4: Hours | AH4: Place of Birth | AI4: Place of Death | AJ4: LBW | AK4: Extreme preterm (<28 weeks) | AL4: Early Premature (28-31 weeks) | AM4: Morderate Premature (<32-33 weeks) | AN4: Late Pre-term (34-36 weeks) | AO4: Aspitartion | AP4: Broncho | AQ4: Congenitall | AR4: Myocarditis | AS4: Cardiac Anomoly | AT4: CHD | AU4: Sepsis | AV4: Respiratory Distress | AW4: Pulmonary Hypertension | AX4: Neonatal Asphyxia | AY4: Meconium Aspiration Syndrome | AZ4: Aspitation Pneumonia | BA4: Necrotinsing Enterocolitis | BB4: Hepatic Cause | BC4: Pneumothorax | BD4: Milk Aspiration | BE4: SIDS | BF4: IUGR | BG4: Twins / Multiple etc | BH4: Hemophagocytic | BI4: Milk Aspiration | BJ4: Cronic Liver Disease | BK4: Others | BL4: Reason for Others / Others | BM4: Preventable (Yes / No)
A5: 1 | B5: B/o Poornima W/o Ramachandra Janatha Colony Uppunda | C5: Kundapura | D5: Byndoor | E5: Hindu | F5: Kharvi | G5: Yes | H5: No | I5: No | J5: No | K5: No | L5: No | M5: No | N5: No | O5: No | P5: Yes | Q5: No | R5: No | S5: No | T5: No | U5: No | V5: No | W5: No | X5: No | Y5: No | Z5: No | AA5: No | AC5: LSCS | AD5: Female | AE5: 0 | AF5: 13 | AG5: 0 | AH5: Pvt. Medical College | AI5: Pvt. Medical College | AJ5: Yes | AK5: No | AL5: No | AM5: Yes | AN5: No | AO5: No | AP5: No | AQ5: No | AR5: No | AS5: No | AT5: No | AU5: No | AV5: No | AW5: No | AX5: No | AY5: No | AZ5: No | BA5: No | BB5: No | BC5: No | BD5: No | BE5: No | BF5: No | BG5: No | BM5: No
A6: 2 | B6: B/o Balkis Banu W/o Musthak Ahamed, Gujjarbettu | C6: Udupi | D6: Kemmannu | E6: Muslim | F6: Muslim | G6: Yes | H6: No | I6: No | J6: No | K6: Yes | L6: No | M6: No | N6: No | O6: No | P6: Yes | Q6: No | R6: No | S6: No | T6: No | U6: No | V6: No | W6: No | X6: No | Y6: No | Z6: No | AA6: No | AC6: LSCS | AD6: Male | AE6: 2 | AF6: 3 | AG6: 0 | AH6: Pvt. Medical College | AI6: Pvt. Medical College | AJ6: No | AK6: No | AL6: No | AM6: No | AN6: No | AO6: No | AP6: No | AQ6: No | AR6: No | AS6: No | AT6: No | AU6: No | AV6: No | AW6: No | AX6: No | AY6: No | AZ6: No | BA6: No | BB6: No | BC6: No | BD6: No | BE6: No | BF6: No | BG6: No | BK6: Yes | BL6: Trisomy 21, VSD, Acute Failure Severe, PAH ASD 7mm | BM6: No
A7: 3 | B7: B/o M Anusha Kumari W/o Shanthiraj Jain Kelagina Karimbyalu Idu | C7: Karkala | D7: Idu | E7: Jain | F7: Jain | G7: Yes | H7: No | I7: No | J7: No | K7: No | L7: No | M7: No | N7: No | O7: No | P7: Yes | Q7: No | R7: No | S7: No | T7: No | U7: No | V7: No | W7: No | X7: No | Y7: No | Z7: No | AA7: No | AC7: LSCS | AD7: Male | AE7: 0 | AF7: 3 | AG7: 0 | AH7: Govt. Hospital | AI7: Govt. Hospital | AJ7: No | AK7: No | AL7: No | AM7: No | AN7: No | AO7: No | AP7: No | AQ7: No | AR7: No | AS7: No | AT7: No | AU7: No | AV7: No | AW7: No | AX7: No | AY7: No | AZ7: No | BA7: No | BB7: No | BC7: No | BD7: No | BE7: No | BF7: No | BG7: No | BK7: Yes | BL7: Multiple Fetal Anomalies Absent Cavum Pellucudum With Septo-Optic Dysplasia? Severe Persistent Pulmonary Hypertension | BM7: No
A8: 4 | B8: Divani Kumari B/o Pinkidevi Kumari W/o Hareram Paswan , Girija Cashew Factory Asodu Korgi | C8: Kundapura | D8: Korgi | E8: Hindu | F8: others | G8: Yes | H8: No | I8: Yes | J8: No | K8: No | L8: No | M8: No | N8: No | O8: No | P8: No | Q8: No | R8: No | S8: No | T8: No | U8: No | V8: No | W8: No | X8: No | Y8: No | Z8: No | AA8: No | AC8: Normal | AD8: Female | AE8: 2 | AF8: 8 | AG8: 0 | AH8: Govt. Hospital | AI8: Home | AJ8: No | AK8: No | AL8: No | AM8: No | AN8: No | AO8: No | AP8: No | AQ8: No | AR8: No | AS8: No | AT8: No | AU8: No | AV8: No | AW8: No | AX8: No | AY8: No | AZ8: No | BA8: No | BB8: No | BC8: No | BD8: No | BE8: Yes | BF8: No | BG8: No | BM8: Yes
A9: 5 | B9: B/o Bhavya W/o Vinoda Uppinakote Uppunda | C9: Kundapura | D9: Byndoor | E9: Hindu | F9: Kharvi | G9: Yes | H9: No | I9: No | J9: No | K9: No | L9: No | M9: No | N9: No | O9: No | P9: No | Q9: No | R9: No | S9: No | T9: No | U9: No | V9: No | W9: No | X9: Yes | Y9: No | Z9: No | AA9: No | AC9: LSCS | AD9: Male | AE9: 0 | AF9: 8 | AG9: 0 | AH9: Govt. Hospital | AI9: Govt. Hospital | AJ9: Yes | AK9: Yes | AL9: No | AM9: No | AN9: No | AO9: No | AP9: No | AQ9: No | AR9: No | AS9: No | AT9: No | AU9: Yes | AV9: No | AW9: No | AX9: No | AY9: No | AZ9: No | BA9: No | BB9: No | BC9: No | BD9: No | BE9: No | BF9: No | BG9: No | BM9: No
A10: 6 | B10: B/o Shriraksha W/o Prlash, Subbumane, Tarapathi Paduvary | C10: Kundapura | D10: Shiroor | E10: Hindu | F10: Kharvi | G10: No | H10: No | I10: No | J10: No | K10: No | L10: No | M10: No | N10: No | O10: No | P10: No | Q10: No | R10: No | S10: No | T10: No | U10: No | V10: No | W10: No | X10: No | Y10: No | Z10: No | AA10: No | AC10: LSCS | AD10: Male | AE10: 0 | AF10: 3 | AG10: 0 | AH10: Pvt. Medical College | AI10: Home | AJ10: No | AK10: No | AL10: No | AM10: Yes | AN10: No | AO10: No | AP10: No | AQ10: No | AR10: No | AS10: No | AT10: No | AU10: No | AV10: No | AW10: No | AX10: No | AY10: No | AZ10: No | BA10: No | BB10: No | BC10: No | BD10: No | BE10: No | BF10: No | BG10: No | BM10: No
A11: 7 | B11: B/o Abeeda Mohammed, Brahmavara | C11: Udupi | D11: Brahmavara | E11: Muslim | F11: Muslim | G11: No | H11: No | I11: No | J11: No | K11: No | L11: No | M11: No | N11: No | O11: No | P11: No | Q11: No | R11: No | S11: No | T11: No | U11: No | V11: No | W11: No | X11: No | Y11: No | Z11: No | AA11: No | AC11: Normal | AD11: Male | AE11: 2 | AF11: 0 | AG11: 0 | AH11: Pvt. Hospital | AI11: Pvt. Hospital | AJ11: No | AK11: No | AL11: No | AM11: No | AN11: No | AO11: No | AP11: No | AQ11: No | AR11: No | AS11: No | AT11: Yes | AU11: No | AV11: No | AW11: No | AX11: No | AY11: No | AZ11: No | BA11: No | BB11: No | BC11: No | BD11: No | BE11: No | BF11: No | BG11: No | BM11: No
A12: 8 | B12: B/o Swathi W/o Yogish Acharya, Darkas House Kanjarkatte, Inna Santhoor Post | C12: Karkala | D12: Inna | E12: Hindu | F12: Acharya | G12: Yes | H12: No | I12: No | J12: No | K12: No | L12: No | M12: No | N12: No | O12: No | P12: No | Q12: No | R12: No | S12: No | T12: No | U12: No | V12: No | W12: No | X12: No | Y12: No | Z12: No | AA12: Yes | AC12: LSCS | AD12: Female | AE12: 0 | AF12: 16 | AG12: 0 | AH12: Pvt. Medical College | AI12: Pvt. Medical College | AJ12: Yes | AK12: No | AL12: No | AM12: No | AN12: No | AO12: No | AP12: No | AQ12: No | AR12: No | AS12: No | AT12: No | AU12: No | AV12: No | AW12: No | AX12: No | AY12: No | AZ12: No | BA12: No | BB12: No | BC12: No | BD12: No | BE12: No | BF12: No | BG12: Yes | BK12: Yes | BL12: Multi Organ Dysfuction syndrome septic shock bilateral grade 3 intra ventricular hemorrhage with moderate Hydrocephalus neonatal seizures acute kidney injury stage 1 anemia of prematurity moderate respiratory distress syndrome very preterm very low birth weight. | BM12: No
A13: 9 | B13: B/o Swathi W/o Yogish Acharya, Darkas House Kanjarkatte, Inna Santhoor Post | C13: Karkala | D13: Inna | E13: Hindu | F13: Acharya | G13: Yes | H13: No | I13: No | J13: No | K13: No | L13: No | M13: No | N13: No | O13: No | P13: No | Q13: No | R13: No | S13: No | T13: No | U13: No | V13: No | W13: No | X13: No | Y13: No | Z13: No | AA13: Yes | AC13: LSCS | AD13: Female | AE13: 0 | AF13: 16 | AG13: 0 | AH13: Pvt. Medical College | AI13: Pvt. Medical College | AJ13: Yes | AK13: No | AL13: No | AM13: No | AN13: No | AO13: No | AP13: No | AQ13: No | AR13: No | AS13: No | AT13: No | AU13: No | AV13: No | AW13: No | AX13: No | AY13: No | AZ13: No | BA13: No | BB13: No | BC13: No | BD13: No | BE13: No | BF13: No | BG13: Yes | BK13: Yes | BL13: Multi Organ Dysfuction syndrome septic shock bilateral grade 3 intra ventricular hemorrhage with moderate Hydrocephalus neonatal seizures acute kidney injury stage 1 anemia of prematurity moderate respiratory distress syndrome very preterm very low birth weight. | BM13: No
A14: 10 | B14: Sanvith B/o Leelavathi W/o Gopala Daivanugraha House, Ballottu, Idu | C14: Karkala | D14: Idu | E14: Hindu | F14: SC | G14: No | H14: No | I14: No | J14: No | K14: No | L14: No | M14: No | N14: No | O14: No | P14: No | Q14: No | R14: No | S14: No | T14: No | U14: No | V14: No | W14: No | X14: No | Y14: No | Z14: No | AA14: No | AC14: LSCS | AD14: Male | AE14: 1 | AF14: 15 | AG14: 0 | AH14: Govt. Hospital | AI14: Pvt. Medical College | AJ14: No | AK14: No | AL14: No | AM14: No | AN14: No | AO14: No | AP14: No | AQ14: No | AR14: No | AS14: No | AT14: No | AU14: No | AV14: No | AW14: No | AX14: No | AY14: No | AZ14: No | BA14: No | BB14: No | BC14: No | BD14: No | BE14: No | BF14: No | BG14: No | BK14: Yes | BL14: Refractory Decompensated Shock Biventricular Failure severe PAH | BM14: No
A15: 11 | B15: Geethika W/o Sharath Kumar D.No.11-66Q Anantha Krishna Nagara Kuthpady | C15: Udupi | D15: Malpe | E15: Hindu | F15: Poojary | G15: No | H15: No | I15: No | J15: No | K15: No | L15: No | M15: No | N15: No | O15: No | P15: No | Q15: No | R15: No | S15: No | T15: No | U15: No | V15: No | W15: No | X15: No | Y15: No | Z15: No | AA15: No | AC15: Normal | AD15: Male | AE15: 0 | AF15: 2 | AG15: 0 | AH15: Pvt. Hospital | AI15: Pvt. Hospital | AJ15: No | AK15: No | AL15: No | AM15: No | AN15: No | AO15: No | AP15: No | AQ15: No | AR15: No | AS15: No | AT15: No | AU15: Yes | AV15: No | AW15: No | AX15: No | AY15: No | AZ15: No | BA15: No | BB15: No | BC15: No | BD15: No | BE15: No | BF15: No | BG15: No | BL15: Early Neonatal Sepsis, Septic shock, multiorgan dysfunction Meningitis | BM15: Yes
A16: 12 | B16: Ashwitha W/o Sharath S Anchan H.No: 9-96 Vanitha Nilaya Kidiyoor padukere | C16: Udupi | D16: Malpe | E16: Hindu | F16: Poojary | G16: No | H16: No | I16: No | J16: No | K16: No | L16: No | M16: No | N16: No | O16: No | P16: No | Q16: No | R16: No | S16: No | T16: No | U16: No | V16: No | W16: No | X16: No | Y16: No | Z16: No | AA16: No | AC16: Normal | AD16: Female | AE16: 0 | AF16: 4 | AG16: 0 | AH16: Pvt. Medical College | AI16: Pvt. Medical College | AJ16: Yes | AK16: Yes | AL16: No | AM16: No | AN16: No | AO16: No | AP16: No | AQ16: No | AR16: No | AS16: No | AT16: No | AU16: No | AV16: Yes | AW16: No | AX16: No | AY16: No | AZ16: No | BA16: No | BB16: No | BC16: No | BD16: No | BE16: No | BF16: No | BG16: No | BL16: Birth weight 780 gms | BM16: No
A17: 13 | B17: B/o Reshma R P W/o Abhishek N S DevuBailu Chantharu Brahmavara 9731660899 | C17: Udupi | D17: Brahmavara | E17: Hindu | F17: SC | G17: Yes | H17: Yes | I17: No | J17: No | K17: No | L17: No | M17: No | N17: No | O17: No | P17: No | Q17: No | R17: No | S17: No | T17: No | U17: No | V17: No | W17: No | X17: No | Y17: No | Z17: No | AA17: No | AC17: LSCS | AD17: Female | AE17: 0 | AF17: 0 | AG17: 4 | AH17: Pvt. Hospital | AI17: Pvt. Medical College | AJ17: No | AK17: No | AL17: No | AM17: No | AN17: No | AO17: No | AP17: No | AQ17: No | AR17: No | AS17: No | AT17: No | AU17: No | AV17: No | AW17: No | AX17: Yes | AY17: Yes | AZ17: No | BA17: No | BB17: No | BC17: No | BD17: No | BE17: No | BF17: No | BG17: No | BL17: severe persistant pulmonary hypertension | BM17: Yes
A18: 14 | B18: B/o Shobha W/o Prasanna Acharya Nandavana Kergal Kirimanjeshwara | C18: Kundapura | D18: Kirimanjeshwara | E18: Hindu | F18: Achary | G18: Yes | H18: No | I18: No | J18: No | K18: No | L18: No | M18: Yes | N18: No | O18: No | P18: Yes | Q18: No | R18: No | S18: No | T18: No | U18: No | V18: No | W18: No | X18: No | Y18: No | Z18: No | AA18: No | AC18: LSCS | AD18: Male | AE18: 0 | AF18: 9 | AG18: 0 | AH18: Pvt. Medical College | AI18: Pvt. Medical College | AJ18: Yes | AK18: Yes | AL18: No | AM18: No | AN18: No | AO18: No | AP18: No | AQ18: No | AR18: No | AS18: No | AT18: No | AU18: No | AV18: Yes | AW18: No | AX18: No | AY18: No | AZ18: No | BA18: No | BB18: No | BC18: No | BD18: No | BE18: No | BF18: No | BG18: No | BM18: No
A19: 15 | B19: Shanya B/o Nethravathi W/o Suresh Dyava, Mogaveera Manki Gujjadi A | C19: Kundapura | D19: Maravanthe | E19: Hindu | F19: Mogaveera | G19: Yes | H19: No | I19: No | J19: Yes | K19: No | L19: No | M19: No | N19: No | O19: No | P19: No | Q19: No | R19: No | S19: No | T19: No | U19: No | V19: No | W19: No | X19: No | Y19: No | Z19: No | AA19: No | AC19: LSCS | AD19: Female | AE19: 1 | AF19: 14 | AG19: 0 | AH19: Pvt. Hospital | AI19: Home | AJ19: No | AK19: No | AL19: No | AM19: No | AN19: No | AO19: No | AP19: No | AQ19: No | AR19: No | AS19: No | AT19: No | AU19: No | AV19: No | AW19: No | AX19: No | AY19: No | AZ19: No | BA19: No | BB19: No | BC19: No | BD19: Yes | BE19: Yes | BF19: No | BG19: No | BL19: PM Reports confirmed | BM19: Yes
A20: 16 | B20: B/o Girija W/o Raghavendra Jolalu Nenchar Kokkarne | C20: Udupi | D20: Kokkarne | E20: Hindu | F20: Kudubi | G20: No | H20: No | I20: No | J20: No | K20: No | L20: No | M20: No | N20: No | O20: No | P20: No | Q20: No | R20: No | S20: No | T20: No | U20: No | V20: No | W20: No | X20: No | Y20: No | Z20: No | AA20: No | AC20: Normal | AD20: Female | AE20: 0 | AF20: 14 | AG20: 0 | AH20: Govt. Hospital | AI20: Pvt. Medical College | AJ20: No | AK20: No | AL20: No | AM20: No | AN20: No | AO20: No | AP20: No | AQ20: No | AR20: No | AS20: No | AT20: No | AU20: No | AV20: No | AW20: Yes | AX20: No | AY20: No | AZ20: No | BA20: No | BB20: No | BC20: No | BD20: No | BE20: No | BF20: No | BG20: No | BK20: Yes | BL20: ? Thyosinemia | BM20: No
A21: 17 | B21: Alia Fathima B/o Rubina W/o Ayub, A R Mansion Nethravathi Hegde Road Kabettu G H Karkala | C21: Karkala | D21: G H Karkala | E21: Muslim | F21: Muslim | G21: Yes | H21: No | I21: No | J21: No | K21: No | L21: No | M21: No | N21: No | O21: No | P21: No | Q21: No | R21: No | S21: No | T21: No | U21: G4 | V21: Yes | W21: No | X21: No | Y21: No | Z21: No | AA21: No | AC21: Normal | AD21: Female | AE21: 0 | AF21: 5 | AG21: 15 | AH21: pvt Hospital | AI21: Home | AJ21: No | AK21: No | AL21: No | AM21: No | AN21: No | AO21: No | AP21: No | AQ21: No | AR21: No | AS21: No | AT21: No | AU21: No | AV21: No | AW21: No | AX21: No | AY21: No | AZ21: No | BA21: No | BB21: No | BC21: No | BD21: No | BE21: No | BF21: No | BG21: No | BK21: Yes | BL21: Spinal Muscular Atrophy lower respiratory infection | BM21: No
A22: 18 | B22: B/o Sarojini W/o Achyutha , Shettybettu, Kervashe Mala | C22: Karkala | D22: Mala | E22: Hindu | F22: SC | G22: Yes | H22: No | I22: No | J22: No | K22: No | L22: No | M22: No | N22: No | O22: No | P22: No | Q22: No | R22: No | S22: No | T22: No | U22: No | V22: No | W22: No | X22: No | Y22: No | Z22: No | AA22: Yes | AC22: Normal | AD22: Female | AE22: 0 | AF22: 7 | AG22: 0 | AH22: Govt. Hospital | AI22: Govt. Hospital | AJ22: Yes | AK22: No | AL22: No | AM22: Yes | AN22: No | AO22: No | AP22: No | AQ22: No | AR22: No | AS22: No | AT22: No | AU22: No | AV22: No | AW22: No | AX22: No | AY22: No | AZ22: No | BA22: No | BB22: No | BC22: No | BD22: No | BE22: No | BF22: No | BG22: No | BM22: Yes
A23: 19 | B23: B/o Kavitha Adiga, W/o Sandeep Jain, Adhikari Nilaya Jyothi Nagara Ajekar | C23: Karkala | D23: Ajekar | E23: Hindu | F23: Jain | G23: Yes | H23: No | I23: No | J23: No | K23: No | L23: No | M23: Yes | N23: No | O23: No | P23: No | Q23: No | R23: No | S23: No | T23: No | U23: Yes | V23: Yes | W23: No | X23: No | Y23: Yes | Z23: No | AA23: No | AC23: LSCS | AD23: Female | AE23: 0 | AF23: 1 | AG23: 0 | AH23: Govt. Hospital | AI23: Govt. Hospital | AJ23: Yes | AK23: No | AL23: Yes | AM23: No | AN23: No | AO23: No | AP23: No | AQ23: No | AR23: No | AS23: No | AT23: No | AU23: No | AV23: Yes | AW23: No | AX23: No | AY23: No | AZ23: No | BA23: No | BB23: No | BC23: No | BD23: No | BE23: No | BF23: No | BG23: No | BK23: Yes | BL23: Skeletal Dysplasia | BM23: No
A24: 20 | B24: B/o Shrudha Kotian W/o Sunil Kundar, Annajigoli Inna | C24: Karkala | D24: Inna | E24: Hindu | F24: Poojary | G24: Yes | H24: No | I24: No | J24: No | K24: No | L24: No | M24: No | N24: No | O24: No | P24: No | Q24: No | R24: No | S24: No | T24: No | U24: No | V24: No | W24: No | X24: No | Y24: No | Z24: No | AA24: Yes | AC24: LSCS | AD24: Female | AE24: 0 | AF24: 1 | AG24: 0 | AH24: Pvt. Medical College | AI24: Pvt. Medical College | AJ24: Yes | AK24: Yes | AL24: No | AM24: No | AN24: No | AO24: No | AP24: No | AQ24: No | AR24: No | AS24: No | AT24: No | AU24: No | AV24: Yes | AW24: No | AX24: No | AY24: No | AZ24: No | BA24: No | BB24: No | BC24: No | BD24: No | BE24: No | BF24: No | BG24: No | BM24: No
A25: 21 | B25: B/o Nazrath Bhanu W/o Sameer B, Kalmanja House, Manipura | C25: Udupi | D25: Manipura | E25: Muslim | F25: Muslim | G25: Yes | H25: No | I25: No | J25: No | K25: No | L25: No | M25: No | N25: No | O25: No | P25: Yes | Q25: No | R25: No | S25: No | T25: No | U25: Yes | V25: No | W25: No | X25: No | Y25: No | Z25: No | AA25: No | AC25: Normal | AD25: Female | AE25: 0 | AF25: 9 | AG25: 0 | AH25: Pvt. Hospital | AI25: Govt. Hospital | AJ25: Yes | AK25: Yes | AL25: No | AM25: No | AN25: No | AO25: No | AP25: No | AQ25: No | AR25: No | AS25: No | AT25: No | AU25: No | AV25: No | AW25: No | AX25: No | AY25: No | AZ25: No | BA25: No | BB25: No | BC25: No | BD25: No | BE25: No | BF25: No | BG25: No | BM25: No
